Workbook

Sheet Strategic Asset Allocation

Sheet Implementation Breakdown
A1: Implementation Breakdown

Sheet Capital Market Assumptions (Exp

Sheet Portfolio Analytics
A1: Annualized Return | B1: {=(GEOMEAN(1+Returns!I3:I122)^12)-1} -> 0.079657947
A2: Standard Deviation | B2: =_xlfn.STDEV.S(Returns!I3:I122)*SQRT(12) -> 0.10920076
A3: Sharpe Ratio | B3: =(B1-3%)/B2 -> 0.45473994
A4: Max Drawdown | B4: =MIN(Returns!L3:L122) -> -0.22131319

Sheet Rebalancing Simulation
A1: START PORFOLIO VALUE | B1: 100000000
A2: ANNUAL SPENDING RATE | B2: 0.0425
A3: MONTHLY SPENDING RATE | B3: =B2/12 -> 0.0035416667
A5: TARGET WEIGHTS
A6: Asset Sleeve | B6: ETF | C6: Target Weight | D6: Min | E6: High
A7: Global Equity | B7: SPY | C7: 0.3 | D7: 0.25 | E7: 0.35
A8: Dev ex-US | B8: EFA | C8: 0.15 | D8: 0.1 | E8: 0.2
A9: EM | B9: EEM | C9: 0.05 | D9: 0.02 | E9: 0.07
A10: Fixed Income | B10: IEF | C10: 0.2 | D10: 0.15 | E10: 0.25
A11: Credit | B11: LQD | C11: 0.1 | D11: 0.05 | E11: 0.15
A12: Real Estate | B12: VNQ | C12: 0.1 | D12: 0.05 | E12: 0.15
A13: Infrastructure | B13: IGF | C13: 0.1 | D13: 0.05 | E13: 0.15
A15: DATE | B15: START VALUE | C15: SPY WT | D15: EFA WT | E15: EEM WT | F15: IEF WT | G15: LQD WT | H15: VNQ WT | I15: IGF WT | J15: SPY$ | K15: EFA$ | L15: EEM$ | M15: IEF$ | N15: LQD$ | O15: VNQ$ | P15: IGF$ | Q15: PRE SPEND VAL | R15: SPENDING | S15: END VALUE | U15: Rebalance | V15: PR $ SPY | W15: PR EFA | X15: PR EEM | Y15: PR IEF | Z15: PRLQD | AA15: PR VNQ | AB15: PR IGF | AC15: END SPY | AD15: END EFA | AE15: END EEM | AF15: END IEF | AG15: END LQD | AH15: END VNQ | AI15: END IGF | AJ15: END VALUE | AK15: REBALANCE
A16: =Returns!A3 -> 42460 | B16: =B1 -> 100000000 | C16: 0.3 | D16: 0.15 | E16: 0.05 | F16: 0.2 | G16: 0.1 | H16: 0.1 | I16: 0.1 | J16: =C16*$B16 -> 30000000 | K16: =D16*$B16 -> 15000000 | L16: =E16*$B16 -> 5000000 | M16: =F16*$B16 -> 20000000 | N16: =G16*$B16 -> 10000000 | O16: =H16*$B16 -> 10000000 | P16: =I16*$B16 -> 10000000 | Q16: =SUM(J16:P16) -> 100000000 | R16: =Q16*$B$3 -> 354166.67 | S16: =Q16-R16 -> 99645833 | U16: =OR( C16<25%,C16>35%, D16<10%,D16>20%, E16<2%, E16>7%, F16<15%,F16>25%, G16<5%, G16>15%, H16<5%, H16>15%, I16<5%, I16>15% ) -> FALSE | V16: =IF($U16=TRUE, $Q16*$C$7, $J16) -> 30000000 | W16: =IF($U16=TRUE, $Q16*$C$8, $K16) -> 15000000 | X16: =IF($U16=TRUE, $Q16*$C$9, $L16) -> 5000000 | Y16: =IF($U16=TRUE, $Q16*$C$10, $M16) -> 20000000 | Z16: =IF($U16=TRUE, $Q16*$C$11, $N16) -> 10000000 | AA16: =IF($U16=TRUE, $Q16*$C$12, $O16) -> 10000000 | AB16: =IF($U16=TRUE, $Q16*$C$13, $P16) -> 10000000 | AC16: =V16*(1-$B$3) -> 29893750 | AD16: =W16*(1-$B$3) -> 14946875 | AE16: =X16*(1-$B$3) -> 4982291.7 | AF16: =Y16*(1-$B$3) -> 19929167 | AG16: =Z16*(1-$B$3) -> 9964583.3 | AH16: =AA16*(1-$B$3) -> 9964583.3 | AI16: =AB16*(1-$B$3) -> 9964583.3 | AJ16: =SUM(AC16:AI16) -> 99645833 | AK16: =OR( V16<25%,V16>35%, W16<10%,W16>20%, X16<2%, X16>7%, Y16<15%,Y16>25%, Z16<5%, Z16>15%, AA16<5%,AA16>15%, AB16<5%, AB16>15% ) -> TRUE
A17: =Returns!A4 -> 42490 | B17: =S16 -> 99645833 | C17: =J17/$Q17 -> 0.29938358 | D17: =K17/$Q17 -> 0.15244136 | E17: =L17/$Q17 -> 0.049940419 | F17: =M17/$Q17 -> 0.19849884 | G17: =N17/$Q17 -> 0.10099885 | H17: =O17/$Q17 -> 0.097083342 | I17: =P17/$Q17 -> 0.10165361 | J17: =J16*(1+Returns!B4) -> 30113810 | K17: =K16*(1+Returns!C4) -> 15333473 | L17: =L16*(1+Returns!D4) -> 5023309.2 | M17: =M16*(1+Returns!E4) -> 19966213 | N17: =N16*(1+Returns!F4) -> 10159075 | O17: =O16*(1+Returns!G4) -> 9765229.4 | P17: =P16*(1+Returns!H4) -> 10224935 | Q17: =SUM(J17:P17) -> 1.0058604e+08 | R17: =Q17*$B$3 -> 356242.24 | S17: =Q17-R17 -> 1.002298e+08 | U17: =OR( C17<25%,C17>35%, D17<10%,D17>20%, E17<2%, E17>7%, F17<15%,F17>25%, G17<5%, G17>15%, H17<5%, H17>15%, I17<5%, I17>15% ) -> FALSE | V17: =IF($U17=TRUE, $Q17*$C$7, $J17) -> 30113810 | W17: =IF($U17=TRUE, $Q17*$C$8, $K17) -> 15333473 | X17: =IF($U17=TRUE, $Q17*$C$9, $L17) -> 5023309.2 | Y17: =IF($U17=TRUE, $Q17*$C$10, $M17) -> 19966213 | Z17: =IF($U17=TRUE, $Q17*$C$11, $N17) -> 10159075 | AA17: =IF($U17=TRUE, $Q17*$C$12, $O17) -> 9765229.4 | AB17: =IF($U17=TRUE, $Q17*$C$13, $P17) -> 10224935 | AC17: =V17*(1-$B$3) -> 30007157 | AD17: =W17*(1-$B$3) -> 15279167 | AE17: =X17*(1-$B$3) -> 5005518.3 | AF17: =Y17*(1-$B$3) -> 19895499 | AG17: =Z17*(1-$B$3) -> 10123095 | AH17: =AA17*(1-$B$3) -> 9730644.2 | AI17: =AB17*(1-$B$3) -> 10188721 | AJ17: =SUM(AC17:AI17) -> 1.002298e+08 | AK17: =OR( V17<25%,V17>35%, W17<10%,W17>20%, X17<2%, X17>7%, Y17<15%,Y17>25%, Z17<5%, Z17>15%, AA17<5%,AA17>15%, AB17<5%, AB17>15% ) -> TRUE
A18: =Returns!A5 -> 42521 | B18: =S17 -> 1.002298e+08 | C18: =J18/Q18 -> 0.30320756 | D18: =K18/$Q18 -> 0.15166949 | E18: =L18/$Q18 -> 0.047862055 | F18: =M18/$Q18 -> 0.19749857 | G18: =N18/$Q18 -> 0.10007115 | H18: =O18/$Q18 -> 0.098843323 | I18: =P18/$Q18 -> 0.10084784 | J18: =J17*(1+Returns!B5) -> 30628503 | K18: =K17*(1+Returns!C5) -> 15320889 | L18: =L17*(1+Returns!D5) -> 4834784.1 | M18: =M17*(1+Returns!E5) -> 19950313 | N18: =N17*(1+Returns!F5) -> 10108685 | O18: =O17*(1+Returns!G5) -> 9984655.5 | P18: =P17*(1+Returns!H5) -> 10187142 | Q18: =SUM(J18:P18) -> 1.0101497e+08 | R18: =Q18*$B$3 -> 357761.36 | S18: =Q18-R18 -> 1.0065721e+08 | U18: =OR( C18<25%,C18>35%, D18<10%,D18>20%, E18<2%, E18>7%, F18<15%,F18>25%, G18<5%, G18>15%, H18<5%, H18>15%, I18<5%, I18>15% ) -> FALSE | V18: =IF($U18=TRUE, $Q18*$C$7, $J18) -> 30628503 | W18: =IF($U18=TRUE, $Q18*$C$8, $K18) -> 15320889 | X18: =IF($U18=TRUE, $Q18*$C$9, $L18) -> 4834784.1 | Y18: =IF($U18=TRUE, $Q18*$C$10, $M18) -> 19950313 | Z18: =IF($U18=TRUE, $Q18*$C$11, $N18) -> 10108685 | AA18: =IF($U18=TRUE, $Q18*$C$12, $O18) -> 9984655.5 | AB18: =IF($U18=TRUE, $Q18*$C$13, $P18) -> 10187142 | AC18: =V18-(1-$B$3) -> 30628502 | AD18: =W18*(1-$B$3) -> 15266628 | AE18: =X18*(1-$B$3) -> 4817660.9 | AF18: =Y18*(1-$B$3) -> 19879656 | AG18: =Z18*(1-$B$3) -> 10072883 | AH18: =AA18*(1-$B$3) -> 9949293.2 | AI18: =AB18*(1-$B$3) -> 10151062 | AJ18: =SUM(AC18:AI18) -> 1.0076569e+08 | AK18: =OR( V18<25%,V18>35%, W18<10%,W18>20%, X18<2%, X18>7%, Y18<15%,Y18>25%, Z18<5%, Z18>15%, AA18<5%,AA18>15%, AB18<5%, AB18>15% ) -> TRUE
A19: =Returns!A6 -> 42551 | B19: =S18 -> 1.0065721e+08 | C19: =J19/Q19 -> 0.29865203 | D19: =K19/$Q19 -> 0.14527148 | E19: =L19/$Q19 -> 0.049124948 | F19: =M19/$Q19 -> 0.19981309 | G19: =N19/$Q19 -> 0.10121585 | H19: =O19/$Q19 -> 0.10374941 | I19: =P19/$Q19 -> 0.10217319 | J19: =J18*(1+Returns!B6) -> 30733820 | K19: =K18*(1+Returns!C6) -> 14949664 | L19: =L18*(1+Returns!D6) -> 5055372.6 | M19: =M18*(1+Returns!E6) -> 20562457 | N19: =N18*(1+Returns!F6) -> 10415967 | O19: =O18*(1+Returns!G6) -> 10676692 | P19: =P18*(1+Returns!H6) -> 10514485 | Q19: =SUM(J19:P19) -> 1.0290846e+08 | R19: =Q19*$B$3 -> 364467.45 | S19: =Q19-R19 -> 1.0254399e+08 | U19: =OR( C19<25%,C19>35%, D19<10%,D19>20%, E19<2%, E19>7%, F19<15%,F19>25%, G19<5%, G19>15%, H19<5%, H19>15%, I19<5%, I19>15% ) -> FALSE | V19: =IF($U19=TRUE, $Q19*$C$7, $J19) -> 30733820 | W19: =IF($U19=TRUE, $Q19*$C$8, $K19) -> 14949664 | X19: =IF($U19=TRUE, $Q19*$C$9, $L19) -> 5055372.6 | Y19: =IF($U19=TRUE, $Q19*$C$10, $M19) -> 20562457 | Z19: =IF($U19=TRUE, $Q19*$C$11, $N19) -> 10415967 | AA19: =IF($U19=TRUE, $Q19*$C$12, $O19) -> 10676692 | AB19: =IF($U19=TRUE, $Q19*$C$13, $P19) -> 10514485 | AC19: =V19-(1-$B$3) -> 30733819 | AD19: =W19*(1-$B$3) -> 14896718 | AE19: =X19*(1-$B$3) -> 5037468.2 | AF19: =Y19*(1-$B$3) -> 20489631 | AG19: =Z19*(1-$B$3) -> 10379077 | AH19: =AA19*(1-$B$3) -> 10638878 | AI19: =AB19*(1-$B$3) -> 10477246 | AJ19: =SUM(AC19:AI19) -> 1.0265284e+08 | AK19: =OR( V19<25%,V19>35%, W19<10%,W19>20%, X19<2%, X19>7%, Y19<15%,Y19>25%, Z19<5%, Z19>15%, AA19<5%,AA19>15%, AB19<5%, AB19>15% ) -> TRUE
A20: =Returns!A7 -> 42582 | B20: =S19 -> 1.0254399e+08 | C20: =J20/Q20 -> 0.30106089 | D20: =K20/$Q20 -> 0.14687112 | E20: =L20/$Q20 -> 0.050340945 | F20: =M20/$Q20 -> 0.19483248 | G20: =N20/$Q20 -> 0.099733934 | H20: =O20/$Q20 -> 0.10519238 | I20: =P20/$Q20 -> 0.10196825 | J20: =J19*(1+Returns!B7) -> 31856633 | K20: =K19*(1+Returns!C7) -> 15541107 | L20: =L19*(1+Returns!D7) -> 5326806.3 | M20: =M19*(1+Returns!E7) -> 20616118 | N20: =N19*(1+Returns!F7) -> 10553305 | O20: =O19*(1+Returns!G7) -> 11130888 | P20: =P19*(1+Returns!H7) -> 10789728 | Q20: =SUM(J20:P20) -> 1.0581459e+08 | R20: =Q20*$B$3 -> 374760 | S20: =Q20-R20 -> 1.0543983e+08 | U20: =OR( C20<25%,C20>35%, D20<10%,D20>20%, E20<2%, E20>7%, F20<15%,F20>25%, G20<5%, G20>15%, H20<5%, H20>15%, I20<5%, I20>15% ) -> FALSE | V20: =IF($U20=TRUE, $Q20*$C$7, $J20) -> 31856633 | W20: =IF($U20=TRUE, $Q20*$C$8, $K20) -> 15541107 | X20: =IF($U20=TRUE, $Q20*$C$9, $L20) -> 5326806.3 | Y20: =IF($U20=TRUE, $Q20*$C$10, $M20) -> 20616118 | Z20: =IF($U20=TRUE, $Q20*$C$11, $N20) -> 10553305 | AA20: =IF($U20=TRUE, $Q20*$C$12, $O20) -> 11130888 | AB20: =IF($U20=TRUE, $Q20*$C$13, $P20) -> 10789728 | AC20: =V20-(1-$B$3) -> 31856632 | AD20: =W20*(1-$B$3) -> 15486066 | AE20: =X20*(1-$B$3) -> 5307940.5 | AF20: =Y20*(1-$B$3) -> 20543103 | AG20: =Z20*(1-$B$3) -> 10515929 | AH20: =AA20*(1-$B$3) -> 11091467 | AI20: =AB20*(1-$B$3) -> 10751515 | AJ20: =SUM(AC20:AI20) -> 1.0555265e+08 | AK20: =OR( V20<25%,V20>35%, W20<10%,W20>20%, X20<2%, X20>7%, Y20<15%,Y20>25%, Z20<5%, Z20>15%, AA20<5%,AA20>15%, AB20<5%, AB20>15% ) -> TRUE
A21: =Returns!A8 -> 42613 | B21: =S20 -> 1.0543983e+08 | C21: =J21/Q21 -> 0.30322479 | D21: =K21/$Q21 -> 0.14852319 | E21: =L21/$Q21 -> 0.051095124 | F21: =M21/$Q21 -> 0.19404636 | G21: =N21/$Q21 -> 0.10047803 | H21: =O21/$Q21 -> 0.10183626 | I21: =P21/$Q21 -> 0.10079625 | J21: =J20*(1+Returns!B8) -> 31895702 | K21: =K20*(1+Returns!C8) -> 15622903 | L21: =L20*(1+Returns!D8) -> 5374609.6 | M21: =M20*(1+Returns!E8) -> 20411408 | N21: =N20*(1+Returns!F8) -> 10569114 | O21: =O20*(1+Returns!G8) -> 10711984 | P21: =P20*(1+Returns!H8) -> 10602586 | Q21: =SUM(J21:P21) -> 1.0518831e+08 | R21: =Q21*$B$3 -> 372541.92 | S21: =Q21-R21 -> 1.0481577e+08 | U21: =OR( C21<25%,C21>35%, D21<10%,D21>20%, E21<2%, E21>7%, F21<15%,F21>25%, G21<5%, G21>15%, H21<5%, H21>15%, I21<5%, I21>15% ) -> FALSE | V21: =IF($U21=TRUE, $Q21*$C$7, $J21) -> 31895702 | W21: =IF($U21=TRUE, $Q21*$C$8, $K21) -> 15622903 | X21: =IF($U21=TRUE, $Q21*$C$9, $L21) -> 5374609.6 | Y21: =IF($U21=TRUE, $Q21*$C$10, $M21) -> 20411408 | Z21: =IF($U21=TRUE, $Q21*$C$11, $N21) -> 10569114 | AA21: =IF($U21=TRUE, $Q21*$C$12, $O21) -> 10711984 | AB21: =IF($U21=TRUE, $Q21*$C$13, $P21) -> 10602586 | AC21: =V21-(1-$B$3) -> 31895701 | AD21: =W21*(1-$B$3) -> 15567572 | AE21: =X21*(1-$B$3) -> 5355574.5 | AF21: =Y21*(1-$B$3) -> 20339118 | AG21: =Z21*(1-$B$3) -> 10531681 | AH21: =AA21*(1-$B$3) -> 10674046 | AI21: =AB21*(1-$B$3) -> 10565036 | AJ21: =SUM(AC21:AI21) -> 1.0492873e+08 | AK21: =OR( V21<25%,V21>35%, W21<10%,W21>20%, X21<2%, X21>7%, Y21<15%,Y21>25%, Z21<5%, Z21>15%, AA21<5%,AA21>15%, AB21<5%, AB21>15% ) -> TRUE
A22: =Returns!A9 -> 42643 | B22: =S21 -> 1.0481577e+08 | C22: =J22/Q22 -> 0.30217933 | D22: =K22/$Q22 -> 0.15002985 | E22: =L22/$Q22 -> 0.052196093 | F22: =M22/$Q22 -> 0.19380008 | G22: =N22/$Q22 -> 0.099864181 | H22: =O22/$Q22 -> 0.099619066 | I22: =P22/$Q22 -> 0.1023114 | J22: =J21*(1+Returns!B9) -> 31897401 | K22: =K21*(1+Returns!C9) -> 15836829 | L22: =L21*(1+Returns!D9) -> 5509707.5 | M22: =M21*(1+Returns!E9) -> 20457120 | N22: =N21*(1+Returns!F9) -> 10541448 | O22: =O21*(1+Returns!G9) -> 10515575 | P22: =P21*(1+Returns!H9) -> 10799771 | Q22: =SUM(J22:P22) -> 1.0555785e+08 | R22: =Q22*$B$3 -> 373850.73 | S22: =Q22-R22 -> 1.05184e+08 | U22: =OR( C22<25%,C22>35%, D22<10%,D22>20%, E22<2%, E22>7%, F22<15%,F22>25%, G22<5%, G22>15%, H22<5%, H22>15%, I22<5%, I22>15% ) -> FALSE | V22: =IF($U22=TRUE, $Q22*$C$7, $J22) -> 31897401 | W22: =IF($U22=TRUE, $Q22*$C$8, $K22) -> 15836829 | X22: =IF($U22=TRUE, $Q22*$C$9, $L22) -> 5509707.5 | Y22: =IF($U22=TRUE, $Q22*$C$10, $M22) -> 20457120 | Z22: =IF($U22=TRUE, $Q22*$C$11, $N22) -> 10541448 | AA22: =IF($U22=TRUE, $Q22*$C$12, $O22) -> 10515575 | AB22: =IF($U22=TRUE, $Q22*$C$13, $P22) -> 10799771 | AC22: =V22-(1-$B$3) -> 31897400 | AD22: =W22*(1-$B$3) -> 15780740 | AE22: =X22*(1-$B$3) -> 5490193.9 | AF22: =Y22*(1-$B$3) -> 20384668 | AG22: =Z22*(1-$B$3) -> 10504114 | AH22: =AA22*(1-$B$3) -> 10478332 | AI22: =AB22*(1-$B$3) -> 10761522 | AJ22: =SUM(AC22:AI22) -> 1.0529697e+08 | AK22: =OR( V22<25%,V22>35%, W22<10%,W22>20%, X22<2%, X22>7%, Y22<15%,Y22>25%, Z22<5%, Z22>15%, AA22<5%,AA22>15%, AB22<5%, AB22>15% ) -> TRUE
A23: =Returns!A10 -> 42674 | B23: =S22 -> 1.05184e+08 | C23: =J23/Q23 -> 0.30376083 | D23: =K23/$Q23 -> 0.15007299 | E23: =L23/$Q23 -> 0.052957971 | F23: =M23/$Q23 -> 0.19528132 | G23: =N23/$Q23 -> 0.10055719 | H23: =O23/$Q23 -> 0.096070643 | I23: =P23/$Q23 -> 0.10129905 | J23: =J22*(1+Returns!B10) -> 31341940 | K23: =K22*(1+Returns!C10) -> 15484480 | L23: =L22*(1+Returns!D10) -> 5464185.5 | M23: =M22*(1+Returns!E10) -> 20149061 | N23: =N22*(1+Returns!F10) -> 10375457 | O23: =O22*(1+Returns!G10) -> 9912536.4 | P23: =P22*(1+Returns!H10) -> 10452002 | Q23: =SUM(J23:P23) -> 1.0317966e+08 | R23: =Q23*$B$3 -> 365427.97 | S23: =Q23-R23 -> 1.0281423e+08 | U23: =OR( C23<25%,C23>35%, D23<10%,D23>20%, E23<2%, E23>7%, F23<15%,F23>25%, G23<5%, G23>15%, H23<5%, H23>15%, I23<5%, I23>15% ) -> FALSE | V23: =IF($U23=TRUE, $Q23*$C$7, $J23) -> 31341940 | W23: =IF($U23=TRUE, $Q23*$C$8, $K23) -> 15484480 | X23: =IF($U23=TRUE, $Q23*$C$9, $L23) -> 5464185.5 | Y23: =IF($U23=TRUE, $Q23*$C$10, $M23) -> 20149061 | Z23: =IF($U23=TRUE, $Q23*$C$11, $N23) -> 10375457 | AA23: =IF($U23=TRUE, $Q23*$C$12, $O23) -> 9912536.4 | AB23: =IF($U23=TRUE, $Q23*$C$13, $P23) -> 10452002 | AC23: =V23-(1-$B$3) -> 31341939 | AD23: =W23*(1-$B$3) -> 15429639 | AE23: =X23*(1-$B$3) -> 5444833.2 | AF23: =Y23*(1-$B$3) -> 20077700 | AG23: =Z23*(1-$B$3) -> 10338711 | AH23: =AA23*(1-$B$3) -> 9877429.5 | AI23: =AB23*(1-$B$3) -> 10414984 | AJ23: =SUM(AC23:AI23) -> 1.0292524e+08 | AK23: =OR( V23<25%,V23>35%, W23<10%,W23>20%, X23<2%, X23>7%, Y23<15%,Y23>25%, Z23<5%, Z23>15%, AA23<5%,AA23>15%, AB23<5%, AB23>15% ) -> TRUE
A24: =Returns!A11 -> 42704 | B24: =S23 -> 1.0281423e+08 | C24: =J24/Q24 -> 0.31845845 | D24: =K24/$Q24 -> 0.14905984 | E24: =L24/$Q24 -> 0.051180397 | F24: =M24/$Q24 -> 0.18905871 | G24: =N24/$Q24 -> 0.098480303 | H24: =O24/$Q24 -> 0.095515074 | I24: =P24/$Q24 -> 0.098247223 | J24: =J23*(1+Returns!B11) -> 32497027 | K24: =K23*(1+Returns!C11) -> 15210780 | L24: =L23*(1+Returns!D11) -> 5222693 | M24: =M23*(1+Returns!E11) -> 19292458 | N24: =N23*(1+Returns!F11) -> 10049402 | O24: =O23*(1+Returns!G11) -> 9746816 | P24: =P23*(1+Returns!H11) -> 10025618 | Q24: =SUM(J24:P24) -> 1.0204479e+08 | R24: =Q24*$B$3 -> 361408.65 | S24: =Q24-R24 -> 1.0168339e+08 | U24: =OR( C24<25%,C24>35%, D24<10%,D24>20%, E24<2%, E24>7%, F24<15%,F24>25%, G24<5%, G24>15%, H24<5%, H24>15%, I24<5%, I24>15% ) -> FALSE | V24: =IF($U24=TRUE, $Q24*$C$7, $J24) -> 32497027 | W24: =IF($U24=TRUE, $Q24*$C$8, $K24) -> 15210780 | X24: =IF($U24=TRUE, $Q24*$C$9, $L24) -> 5222693 | Y24: =IF($U24=TRUE, $Q24*$C$10, $M24) -> 19292458 | Z24: =IF($U24=TRUE, $Q24*$C$11, $N24) -> 10049402 | AA24: =IF($U24=TRUE, $Q24*$C$12, $O24) -> 9746816 | AB24: =IF($U24=TRUE, $Q24*$C$13, $P24) -> 10025618 | AC24: =V24-(1-$B$3) -> 32497026 | AD24: =W24*(1-$B$3) -> 15156909 | AE24: =X24*(1-$B$3) -> 5204196 | AF24: =Y24*(1-$B$3) -> 19224130 | AG24: =Z24*(1-$B$3) -> 10013811 | AH24: =AA24*(1-$B$3) -> 9712296 | AI24: =AB24*(1-$B$3) -> 9990110.3 | AJ24: =SUM(AC24:AI24) -> 1.0179848e+08 | AK24: =OR( V24<25%,V24>35%, W24<10%,W24>20%, X24<2%, X24>7%, Y24<15%,Y24>25%, Z24<5%, Z24>15%, AA24<5%,AA24>15%, AB24<5%, AB24>15% ) -> TRUE
A25: =Returns!A12 -> 42735 | B25: =S24 -> 1.0168339e+08 | C25: =J25/Q25 -> 0.31912617 | D25: =K25/$Q25 -> 0.15035492 | E25: =L25/$Q25 -> 0.050149935 | F25: =M25/$Q25 -> 0.1854977 | G25: =N25/$Q25 -> 0.09755293 | H25: =O25/$Q25 -> 0.098327325 | I25: =P25/$Q25 -> 0.098991025 | J25: =J24*(1+Returns!B12) -> 33152709 | K25: =K24*(1+Returns!C12) -> 15619757 | L25: =L24*(1+Returns!D12) -> 5209871.2 | M25: =M24*(1+Returns!E12) -> 19270595 | N25: =N24*(1+Returns!F12) -> 10134374 | O25: =O24*(1+Returns!G12) -> 10214823 | P25: =P24*(1+Returns!H12) -> 10283772 | Q25: =SUM(J25:P25) -> 1.038859e+08 | R25: =Q25*$B$3 -> 367929.23 | S25: =Q25-R25 -> 1.0351797e+08 | U25: =OR( C25<25%,C25>35%, D25<10%,D25>20%, E25<2%, E25>7%, F25<15%,F25>25%, G25<5%, G25>15%, H25<5%, H25>15%, I25<5%, I25>15% ) -> FALSE | V25: =IF($U25=TRUE, $Q25*$C$7, $J25) -> 33152709 | W25: =IF($U25=TRUE, $Q25*$C$8, $K25) -> 15619757 | X25: =IF($U25=TRUE, $Q25*$C$9, $L25) -> 5209871.2 | Y25: =IF($U25=TRUE, $Q25*$C$10, $M25) -> 19270595 | Z25: =IF($U25=TRUE, $Q25*$C$11, $N25) -> 10134374 | AA25: =IF($U25=TRUE, $Q25*$C$12, $O25) -> 10214823 | AB25: =IF($U25=TRUE, $Q25*$C$13, $P25) -> 10283772 | AC25: =V25-(1-$B$3) -> 33152708 | AD25: =W25*(1-$B$3) -> 15564437 | AE25: =X25*(1-$B$3) -> 5191419.6 | AF25: =Y25*(1-$B$3) -> 19202345 | AG25: =Z25*(1-$B$3) -> 10098481 | AH25: =AA25*(1-$B$3) -> 10178645 | AI25: =AB25*(1-$B$3) -> 10247350 | AJ25: =SUM(AC25:AI25) -> 1.0363539e+08 | AK25: =OR( V25<25%,V25>35%, W25<10%,W25>20%, X25<2%, X25>7%, Y25<15%,Y25>25%, Z25<5%, Z25>15%, AA25<5%,AA25>15%, AB25<5%, AB25>15% ) -> TRUE
A26: =Returns!A13 -> 42766 | B26: =S25 -> 1.0351797e+08 | C26: =J26/Q26 -> 0.31970494 | D26: =K26/$Q26 -> 0.15285405 | E26: =L26/$Q26 -> 0.052636956 | F26: =M26/$Q26 -> 0.18296527 | G26: =N26/$Q26 -> 0.096134338 | H26: =O26/$Q26 -> 0.096590964 | I26: =P26/$Q26 -> 0.099113485 | J26: =J25*(1+Returns!B13) -> 33748938 | K26: =K25*(1+Returns!C13) -> 16135696 | L26: =L25*(1+Returns!D13) -> 5556502.7 | M26: =M25*(1+Returns!E13) -> 19314320 | N26: =N25*(1+Returns!F13) -> 10148207 | O26: =O25*(1+Returns!G13) -> 10196409 | P26: =P25*(1+Returns!H13) -> 10462694 | Q26: =SUM(J26:P26) -> 1.0556277e+08 | R26: =Q26*$B$3 -> 373868.13 | S26: =Q26-R26 -> 1.051889e+08 | U26: =OR( C26<25%,C26>35%, D26<10%,D26>20%, E26<2%, E26>7%, F26<15%,F26>25%, G26<5%, G26>15%, H26<5%, H26>15%, I26<5%, I26>15% ) -> FALSE | V26: =IF($U26=TRUE, $Q26*$C$7, $J26) -> 33748938 | W26: =IF($U26=TRUE, $Q26*$C$8, $K26) -> 16135696 | X26: =IF($U26=TRUE, $Q26*$C$9, $L26) -> 5556502.7 | Y26: =IF($U26=TRUE, $Q26*$C$10, $M26) -> 19314320 | Z26: =IF($U26=TRUE, $Q26*$C$11, $N26) -> 10148207 | AA26: =IF($U26=TRUE, $Q26*$C$12, $O26) -> 10196409 | AB26: =IF($U26=TRUE, $Q26*$C$13, $P26) -> 10462694 | AC26: =V26-(1-$B$3) -> 33748937 | AD26: =W26*(1-$B$3) -> 16078549 | AE26: =X26*(1-$B$3) -> 5536823.4 | AF26: =Y26*(1-$B$3) -> 19245915 | AG26: =Z26*(1-$B$3) -> 10112265 | AH26: =AA26*(1-$B$3) -> 10160297 | AI26: =AB26*(1-$B$3) -> 10425638 | AJ26: =SUM(AC26:AI26) -> 1.0530843e+08 | AK26: =OR( V26<25%,V26>35%, W26<10%,W26>20%, X26<2%, X26>7%, Y26<15%,Y26>25%, Z26<5%, Z26>15%, AA26<5%,AA26>15%, AB26<5%, AB26>15% ) -> TRUE
A27: =Returns!A14 -> 42794 | B27: =S26 -> 1.051889e+08 | C27: =J27/Q27 -> 0.32447694 | D27: =K27/$Q27 -> 0.1510359 | E27: =L27/$Q27 -> 0.052293927 | F27: =M27/$Q27 -> 0.18004294 | G27: =N27/$Q27 -> 0.095080836 | H27: =O27/$Q27 -> 0.097627523 | I27: =P27/$Q27 -> 0.099441933 | J27: =J26*(1+Returns!B14) -> 35077289 | K27: =K26*(1+Returns!C14) -> 16327601 | L27: =L26*(1+Returns!D14) -> 5653188.1 | M27: =M26*(1+Returns!E14) -> 19463381 | N27: =N26*(1+Returns!F14) -> 10278629 | O27: =O26*(1+Returns!G14) -> 10553936 | P27: =P26*(1+Returns!H14) -> 10750081 | Q27: =SUM(J27:P27) -> 1.081041e+08 | R27: =Q27*$B$3 -> 382868.7 | S27: =Q27-R27 -> 1.0772124e+08 | U27: =OR( C27<25%,C27>35%, D27<10%,D27>20%, E27<2%, E27>7%, F27<15%,F27>25%, G27<5%, G27>15%, H27<5%, H27>15%, I27<5%, I27>15% ) -> FALSE | V27: =IF($U27=TRUE, $Q27*$C$7, $J27) -> 35077289 | W27: =IF($U27=TRUE, $Q27*$C$8, $K27) -> 16327601 | X27: =IF($U27=TRUE, $Q27*$C$9, $L27) -> 5653188.1 | Y27: =IF($U27=TRUE, $Q27*$C$10, $M27) -> 19463381 | Z27: =IF($U27=TRUE, $Q27*$C$11, $N27) -> 10278629 | AA27: =IF($U27=TRUE, $Q27*$C$12, $O27) -> 10553936 | AB27: =IF($U27=TRUE, $Q27*$C$13, $P27) -> 10750081 | AC27: =V27-(1-$B$3) -> 35077288 | AD27: =W27*(1-$B$3) -> 16269774 | AE27: =X27*(1-$B$3) -> 5633166.4 | AF27: =Y27*(1-$B$3) -> 19394448 | AG27: =Z27*(1-$B$3) -> 10242225 | AH27: =AA27*(1-$B$3) -> 10516557 | AI27: =AB27*(1-$B$3) -> 10712008 | AJ27: =SUM(AC27:AI27) -> 1.0784547e+08 | AK27: =OR( V27<25%,V27>35%, W27<10%,W27>20%, X27<2%, X27>7%, Y27<15%,Y27>25%, Z27<5%, Z27>15%, AA27<5%,AA27>15%, AB27<5%, AB27>15% ) -> TRUE
A28: =Returns!A15 -> 42825 | B28: =S27 -> 1.0772124e+08 | C28: =J28/Q28 -> 0.32214499 | D28: =K28/$Q28 -> 0.15463209 | E28: =L28/$Q28 -> 0.053772644 | F28: =M28/$Q28 -> 0.178696 | G28: =N28/$Q28 -> 0.094020568 | H28: =O28/$Q28 -> 0.094467285 | I28: =P28/$Q28 -> 0.10226642 | J28: =J27*(1+Returns!B15) -> 35116358 | K28: =K27*(1+Returns!C15) -> 16856124 | L28: =L27*(1+Returns!D15) -> 5861644.5 | M28: =M27*(1+Returns!E15) -> 19479281 | N28: =N27*(1+Returns!F15) -> 10248987 | O28: =O27*(1+Returns!G15) -> 10297683 | P28: =P27*(1+Returns!H15) -> 11147850 | Q28: =SUM(J28:P28) -> 1.0900793e+08 | R28: =Q28*$B$3 -> 386069.74 | S28: =Q28-R28 -> 1.0862186e+08 | U28: =OR( C28<25%,C28>35%, D28<10%,D28>20%, E28<2%, E28>7%, F28<15%,F28>25%, G28<5%, G28>15%, H28<5%, H28>15%, I28<5%, I28>15% ) -> FALSE | V28: =IF($U28=TRUE, $Q28*$C$7, $J28) -> 35116358 | W28: =IF($U28=TRUE, $Q28*$C$8, $K28) -> 16856124 | X28: =IF($U28=TRUE, $Q28*$C$9, $L28) -> 5861644.5 | Y28: =IF($U28=TRUE, $Q28*$C$10, $M28) -> 19479281 | Z28: =IF($U28=TRUE, $Q28*$C$11, $N28) -> 10248987 | AA28: =IF($U28=TRUE, $Q28*$C$12, $O28) -> 10297683 | AB28: =IF($U28=TRUE, $Q28*$C$13, $P28) -> 11147850 | AC28: =V28-(1-$B$3) -> 35116357 | AD28: =W28*(1-$B$3) -> 16796425 | AE28: =X28*(1-$B$3) -> 5840884.5 | AF28: =Y28*(1-$B$3) -> 19410291 | AG28: =Z28*(1-$B$3) -> 10212689 | AH28: =AA28*(1-$B$3) -> 10261212 | AI28: =AB28*(1-$B$3) -> 11108368 | AJ28: =SUM(AC28:AI28) -> 1.0874623e+08 | AK28: =OR( V28<25%,V28>35%, W28<10%,W28>20%, X28<2%, X28>7%, Y28<15%,Y28>25%, Z28<5%, Z28>15%, AA28<5%,AA28>15%, AB28<5%, AB28>15% ) -> TRUE
A29: =Returns!A16 -> 42855 | B29: =S28 -> 1.0862186e+08 | C29: =J29/Q29 -> 0.32127753 | D29: =K29/$Q29 -> 0.15640643 | E29: =L29/$Q29 -> 0.054003596 | F29: =M29/$Q29 -> 0.17837344 | G29: =N29/$Q29 -> 0.093956594 | H29: =O29/$Q29 -> 0.093510246 | I29: =P29/$Q29 -> 0.10247217 | J29: =J28*(1+Returns!B16) -> 35464583 | K29: =K28*(1+Returns!C16) -> 17265101 | L29: =L28*(1+Returns!D16) -> 5961248 | M29: =M28*(1+Returns!E16) -> 19689953 | N29: =N28*(1+Returns!F16) -> 10371505 | O29: =O28*(1+Returns!G16) -> 10322234 | P29: =P28*(1+Returns!H16) -> 11311506 | Q29: =SUM(J29:P29) -> 1.1038613e+08 | R29: =Q29*$B$3 -> 390950.88 | S29: =Q29-R29 -> 1.0999518e+08 | U29: =OR( C29<25%,C29>35%, D29<10%,D29>20%, E29<2%, E29>7%, F29<15%,F29>25%, G29<5%, G29>15%, H29<5%, H29>15%, I29<5%, I29>15% ) -> FALSE | V29: =IF($U29=TRUE, $Q29*$C$7, $J29) -> 35464583 | W29: =IF($U29=TRUE, $Q29*$C$8, $K29) -> 17265101 | X29: =IF($U29=TRUE, $Q29*$C$9, $L29) -> 5961248 | Y29: =IF($U29=TRUE, $Q29*$C$10, $M29) -> 19689953 | Z29: =IF($U29=TRUE, $Q29*$C$11, $N29) -> 10371505 | AA29: =IF($U29=TRUE, $Q29*$C$12, $O29) -> 10322234 | AB29: =IF($U29=TRUE, $Q29*$C$13, $P29) -> 11311506 | AC29: =V29-(1-$B$3) -> 35464582 | AD29: =W29*(1-$B$3) -> 17203953 | AE29: =X29*(1-$B$3) -> 5940135.3 | AF29: =Y29*(1-$B$3) -> 19620218 | AG29: =Z29*(1-$B$3) -> 10334772 | AH29: =AA29*(1-$B$3) -> 10285676 | AI29: =AB29*(1-$B$3) -> 11271445 | AJ29: =SUM(AC29:AI29) -> 1.1012078e+08 | AK29: =OR( V29<25%,V29>35%, W29<10%,W29>20%, X29<2%, X29>7%, Y29<15%,Y29>25%, Z29<5%, Z29>15%, AA29<5%,AA29>15%, AB29<5%, AB29>15% ) -> TRUE
... A135: =Returns!A122 -> 46081 | B135: =S134 -> 2.2272433e+08 | C135: =J135/Q135 -> 0.51378408 | D135: =K135/$Q135 -> 0.14549408 | E135: =L135/$Q135 -> 0.047956909 | F135: =M135/$Q135 -> 0.08573511 | G135: =N135/$Q135 -> 0.048912384 | H135: =O135/$Q135 -> 0.064395186 | I135: =P135/$Q135 -> 0.093722255 | J135: =J134*(1+Returns!B122) -> 1.1580431e+08 | K135: =K134*(1+Returns!C122) -> 32793624 | L135: =L134*(1+Returns!D122) -> 10809243 | M135: =M134*(1+Returns!E122) -> 19324257 | N135: =N134*(1+Returns!F122) -> 11024602 | O135: =O134*(1+Returns!G122) -> 14514347 | P135: =P134*(1+Returns!H122) -> 21124519 | Q135: =SUM(J135:P135) -> 2.2539491e+08 | R135: =Q135*$B$3 -> 798273.63 | S135: =Q135-R135 -> 2.2459663e+08 | U135: =OR( C135<25%,C135>35%, D135<10%,D135>20%, E135<2%, E135>7%, F135<15%,F135>25%, G135<5%, G135>15%, H135<5%, H135>15%, I135<5%, I135>15% ) -> TRUE | V135: =IF($U135=TRUE, $Q135*$C$7, $J135) -> 67618472 | W135: =IF($U135=TRUE, $Q135*$C$8, $K135) -> 33809236 | X135: =IF($U135=TRUE, $Q135*$C$9, $L135) -> 11269745 | Y135: =IF($U135=TRUE, $Q135*$C$10, $M135) -> 45078981 | Z135: =IF($U135=TRUE, $Q135*$C$11, $N135) -> 22539491 | AA135: =IF($U135=TRUE, $Q135*$C$12, $O135) -> 22539491 | AB135: =IF($U135=TRUE, $Q135*$C$13, $P135) -> 22539491 | AC135: =V135-(1-$B$3) -> 67618471 | AD135: =W135*(1-$B$3) -> 33689495 | AE135: =X135*(1-$B$3) -> 11229832 | AF135: =Y135*(1-$B$3) -> 44919327 | AG135: =Z135*(1-$B$3) -> 22459663 | AH135: =AA135*(1-$B$3) -> 22459663 | AI135: =AB135*(1-$B$3) -> 22459663 | AJ135: =SUM(AC135:AI135) -> 2.2483611e+08 | AK135: =OR( V135<25%,V135>35%, W135<10%,W135>20%, X135<2%, X135>7%, Y135<15%,Y135>25%, Z135<5%, Z135>15%, AA135<5%,AA135>15%, AB135<5%, AB135>15% ) -> TRUE

Sheet Sheet2
A1: START PORFOLIO VALUE | B1: 100000000
A2: ANNUAL SPENDING RATE | B2: 0.0425
A3: MONTHLY SPENDING RATE | B3: =B2/12 -> 0.0035416667
A5: TARGET WEIGHTS
A6: Asset Sleeve | B6: ETF | C6: Target Weight | D6: Min | E6: High
A7: Global Equity | B7: SPY | C7: 0.3 | D7: 0.25 | E7: 0.35
A8: Dev ex-US | B8: EFA | C8: 0.15 | D8: 0.1 | E8: 0.2
A9: EM | B9: EEM | C9: 0.05 | D9: 0.02 | E9: 0.07
A10: Fixed Income | B10: IEF | C10: 0.2 | D10: 0.15 | E10: 0.25
A11: Credit | B11: LQD | C11: 0.1 | D11: 0.05 | E11: 0.15
A12: Real Estate | B12: VNQ | C12: 0.1 | D12: 0.05 | E12: 0.15
A13: Infrastructure | B13: IGF | C13: 0.1 | D13: 0.05 | E13: 0.15
A15: DATE | B15: START VALUE | C15: SPY WT | D15: EFA WT | E15: EEM WT | F15: IEF WT | G15: LQD WT | H15: VNQ WT | I15: IGF WT | J15: SPY$ | K15: EFA$ | L15: EEM$ | M15: IEF$ | N15: LQD$ | O15: VNQ$ | P15: IGF$ | Q15: PRE SPEND VAL | R15: SPENDING | S15: END VALUE | T15: Rebalance | U15: Post-rebalance $ SPY | V15: PR EFA | W15: PR EEM | X15: PR IEF | Y15: PRLQD | Z15: PR VNQ | AA15: PR IGF | AB15: END SPY | AC15: END EFA | AD15: END EEM | AE15: END IEF | AF15: END LQD | AG15: END VNQ | AH15: END IGF | AI15: END VALUE
A16: =Returns!A3 -> 42460 | B16: =B1 -> 100000000 | C16: 0.3 | D16: 0.15 | E16: 0.05 | F16: 0.2 | G16: 0.1 | H16: 0.1 | I16: 0.1 | J16: =C16*$B16 -> 30000000 | K16: =D16*$B16 -> 15000000 | L16: =E16*$B16 -> 5000000 | M16: =F16*$B16 -> 20000000 | N16: =G16*$B16 -> 10000000 | O16: =H16*$B16 -> 10000000 | P16: =I16*$B16 -> 10000000 | Q16: =SUM(J16:P16) -> 100000000 | R16: =Q16*$B$3 -> 354166.67 | S16: =Q16-R16 -> 99645833 | T16: =OR( C16<25%,C16>35%, D16<10%,D16>20%, E16<2%, E16>7%, F16<15%,F16>25%, G16<5%, G16>15%, H16<5%, H16>15%, I16<5%, I16>15% ) -> FALSE | U16: =IF($T16=TRUE, $Q16*$C$7, $J16) -> 30000000 | V16: =IF($T16=TRUE, $Q16*$C$8, $K16) -> 15000000 | W16: =IF($T16=TRUE, $Q16*$C$9, $L16) -> 5000000 | X16: =IF($T16=TRUE, $Q16*$C$10, $M16) -> 20000000 | Y16: =IF($T16=TRUE, $Q16*$C$11, $N16) -> 10000000 | Z16: =IF($T16=TRUE, $Q16*$C$12, $O16) -> 10000000 | AA16: =IF($T16=TRUE, $Q16*$C$13, $P16) -> 10000000 | AB16: =U16*(1-$B$3) -> 29893750 | AC16: =V16*(1-$B$3) -> 14946875 | AD16: =W16*(1-$B$3) -> 4982291.7 | AE16: =X16*(1-$B$3) -> 19929167 | AF16: =Y16*(1-$B$3) -> 9964583.3 | AG16: =Z16*(1-$B$3) -> 9964583.3 | AH16: =AA16*(1-$B$3) -> 9964583.3 | AI16: =SUM(AB16:AH16) -> 99645833
A17: =Returns!A4 -> 42490 | B17: =S16 -> 99645833 | C17: =J17/$Q17 -> 0.29938358 | D17: =K17/$Q17 -> 0.15244136 | E17: =L17/$Q17 -> 0.049940419 | F17: =M17/$Q17 -> 0.19849884 | G17: =N17/$Q17 -> 0.10099885 | H17: =O17/$Q17 -> 0.097083342 | I17: =P17/$Q17 -> 0.10165361 | J17: =J16*(1+Returns!B4) -> 30113810 | K17: =K16*(1+Returns!C4) -> 15333473 | L17: =L16*(1+Returns!D4) -> 5023309.2 | M17: =M16*(1+Returns!E4) -> 19966213 | N17: =N16*(1+Returns!F4) -> 10159075 | O17: =O16*(1+Returns!G4) -> 9765229.4 | P17: =P16*(1+Returns!H4) -> 10224935 | Q17: =SUM(J17:P17) -> 1.0058604e+08 | R17: =Q17*$B$3 -> 356242.24 | S17: =Q17-R17 -> 1.002298e+08 | T17: =OR( C17<25%,C17>35%, D17<10%,D17>20%, E17<2%, E17>7%, F17<15%,F17>25%, G17<5%, G17>15%, H17<5%, H17>15%, I17<5%, I17>15% ) -> FALSE | U17: =IF($T17=TRUE, $Q17*$C$7, $J17) -> 30113810 | V17: =IF($T17=TRUE, $Q17*$C$8, $K17) -> 15333473 | W17: =IF($T17=TRUE, $Q17*$C$9, $L17) -> 5023309.2 | X17: =IF($T17=TRUE, $Q17*$C$10, $M17) -> 19966213 | Y17: =IF($T17=TRUE, $Q17*$C$11, $N17) -> 10159075 | Z17: =IF($T17=TRUE, $Q17*$C$12, $O17) -> 9765229.4 | AA17: =IF($T17=TRUE, $Q17*$C$13, $P17) -> 10224935 | AB17: =U17*(1-$B$3) -> 30007157 | AC17: =V17*(1-$B$3) -> 15279167 | AD17: =W17*(1-$B$3) -> 5005518.3 | AE17: =X17*(1-$B$3) -> 19895499 | AF17: =Y17*(1-$B$3) -> 10123095 | AG17: =Z17*(1-$B$3) -> 9730644.2 | AH17: =AA17*(1-$B$3) -> 10188721 | AI17: =SUM(AB17:AH17) -> 1.002298e+08
A18: =Returns!A5 -> 42521 | B18: =S17 -> 1.002298e+08 | C18: =J18/Q18 -> 0.30320756 | D18: =K18/$Q18 -> 0.15166949 | E18: =L18/$Q18 -> 0.047862055 | F18: =M18/$Q18 -> 0.19749857 | G18: =N18/$Q18 -> 0.10007115 | H18: =O18/$Q18 -> 0.098843323 | I18: =P18/$Q18 -> 0.10084784 | J18: =J17*(1+Returns!B5) -> 30628503 | K18: =K17*(1+Returns!C5) -> 15320889 | L18: =L17*(1+Returns!D5) -> 4834784.1 | M18: =M17*(1+Returns!E5) -> 19950313 | N18: =N17*(1+Returns!F5) -> 10108685 | O18: =O17*(1+Returns!G5) -> 9984655.5 | P18: =P17*(1+Returns!H5) -> 10187142 | Q18: =SUM(J18:P18) -> 1.0101497e+08 | R18: =Q18*$B$3 -> 357761.36 | S18: =Q18-R18 -> 1.0065721e+08 | T18: =OR( C18<25%,C18>35%, D18<10%,D18>20%, E18<2%, E18>7%, F18<15%,F18>25%, G18<5%, G18>15%, H18<5%, H18>15%, I18<5%, I18>15% ) -> FALSE | U18: =IF($T18=TRUE, $Q18*$C$7, $J18) -> 30628503 | V18: =IF($T18=TRUE, $Q18*$C$8, $K18) -> 15320889 | W18: =IF($T18=TRUE, $Q18*$C$9, $L18) -> 4834784.1 | X18: =IF($T18=TRUE, $Q18*$C$10, $M18) -> 19950313 | Y18: =IF($T18=TRUE, $Q18*$C$11, $N18) -> 10108685 | Z18: =IF($T18=TRUE, $Q18*$C$12, $O18) -> 9984655.5 | AA18: =IF($T18=TRUE, $Q18*$C$13, $P18) -> 10187142 | AB18: =U18-(1-$B$3) -> 30628502 | AC18: =V18*(1-$B$3) -> 15266628 | AD18: =W18*(1-$B$3) -> 4817660.9 | AE18: =X18*(1-$B$3) -> 19879656 | AF18: =Y18*(1-$B$3) -> 10072883 | AG18: =Z18*(1-$B$3) -> 9949293.2 | AH18: =AA18*(1-$B$3) -> 10151062 | AI18: =SUM(AB18:AH18) -> 1.0076569e+08
A19: =Returns!A6 -> 42551 | B19: =S18 -> 1.0065721e+08 | C19: =J19/Q19 -> 0.29865203 | D19: =K19/$Q19 -> 0.14527148 | E19: =L19/$Q19 -> 0.049124948 | F19: =M19/$Q19 -> 0.19981309 | G19: =N19/$Q19 -> 0.10121585 | H19: =O19/$Q19 -> 0.10374941 | I19: =P19/$Q19 -> 0.10217319 | J19: =J18*(1+Returns!B6) -> 30733820 | K19: =K18*(1+Returns!C6) -> 14949664 | L19: =L18*(1+Returns!D6) -> 5055372.6 | M19: =M18*(1+Returns!E6) -> 20562457 | N19: =N18*(1+Returns!F6) -> 10415967 | O19: =O18*(1+Returns!G6) -> 10676692 | P19: =P18*(1+Returns!H6) -> 10514485 | Q19: =SUM(J19:P19) -> 1.0290846e+08 | R19: =Q19*$B$3 -> 364467.45 | S19: =Q19-R19 -> 1.0254399e+08 | T19: =OR( C19<25%,C19>35%, D19<10%,D19>20%, E19<2%, E19>7%, F19<15%,F19>25%, G19<5%, G19>15%, H19<5%, H19>15%, I19<5%, I19>15% ) -> FALSE | U19: =IF($T19=TRUE, $Q19*$C$7, $J19) -> 30733820 | V19: =IF($T19=TRUE, $Q19*$C$8, $K19) -> 14949664 | W19: =IF($T19=TRUE, $Q19*$C$9, $L19) -> 5055372.6 | X19: =IF($T19=TRUE, $Q19*$C$10, $M19) -> 20562457 | Y19: =IF($T19=TRUE, $Q19*$C$11, $N19) -> 10415967 | Z19: =IF($T19=TRUE, $Q19*$C$12, $O19) -> 10676692 | AA19: =IF($T19=TRUE, $Q19*$C$13, $P19) -> 10514485 | AB19: =U19-(1-$B$3) -> 30733819 | AC19: =V19*(1-$B$3) -> 14896718 | AD19: =W19*(1-$B$3) -> 5037468.2 | AE19: =X19*(1-$B$3) -> 20489631 | AF19: =Y19*(1-$B$3) -> 10379077 | AG19: =Z19*(1-$B$3) -> 10638878 | AH19: =AA19*(1-$B$3) -> 10477246 | AI19: =SUM(AB19:AH19) -> 1.0265284e+08
A20: =Returns!A7 -> 42582 | B20: =S19 -> 1.0254399e+08 | C20: =J20/Q20 -> 0.30106089 | D20: =K20/$Q20 -> 0.14687112 | E20: =L20/$Q20 -> 0.050340945 | F20: =M20/$Q20 -> 0.19483248 | G20: =N20/$Q20 -> 0.099733934 | H20: =O20/$Q20 -> 0.10519238 | I20: =P20/$Q20 -> 0.10196825 | J20: =J19*(1+Returns!B7) -> 31856633 | K20: =K19*(1+Returns!C7) -> 15541107 | L20: =L19*(1+Returns!D7) -> 5326806.3 | M20: =M19*(1+Returns!E7) -> 20616118 | N20: =N19*(1+Returns!F7) -> 10553305 | O20: =O19*(1+Returns!G7) -> 11130888 | P20: =P19*(1+Returns!H7) -> 10789728 | Q20: =SUM(J20:P20) -> 1.0581459e+08 | R20: =Q20*$B$3 -> 374760 | S20: =Q20-R20 -> 1.0543983e+08 | T20: =OR( C20<25%,C20>35%, D20<10%,D20>20%, E20<2%, E20>7%, F20<15%,F20>25%, G20<5%, G20>15%, H20<5%, H20>15%, I20<5%, I20>15% ) -> FALSE | U20: =IF($T20=TRUE, $Q20*$C$7, $J20) -> 31856633 | V20: =IF($T20=TRUE, $Q20*$C$8, $K20) -> 15541107 | W20: =IF($T20=TRUE, $Q20*$C$9, $L20) -> 5326806.3 | X20: =IF($T20=TRUE, $Q20*$C$10, $M20) -> 20616118 | Y20: =IF($T20=TRUE, $Q20*$C$11, $N20) -> 10553305 | Z20: =IF($T20=TRUE, $Q20*$C$12, $O20) -> 11130888 | AA20: =IF($T20=TRUE, $Q20*$C$13, $P20) -> 10789728 | AB20: =U20-(1-$B$3) -> 31856632 | AC20: =V20*(1-$B$3) -> 15486066 | AD20: =W20*(1-$B$3) -> 5307940.5 | AE20: =X20*(1-$B$3) -> 20543103 | AF20: =Y20*(1-$B$3) -> 10515929 | AG20: =Z20*(1-$B$3) -> 11091467 | AH20: =AA20*(1-$B$3) -> 10751515 | AI20: =SUM(AB20:AH20) -> 1.0555265e+08
A21: =Returns!A8 -> 42613 | B21: =S20 -> 1.0543983e+08 | C21: =J21/Q21 -> 0.30322479 | D21: =K21/$Q21 -> 0.14852319 | E21: =L21/$Q21 -> 0.051095124 | F21: =M21/$Q21 -> 0.19404636 | G21: =N21/$Q21 -> 0.10047803 | H21: =O21/$Q21 -> 0.10183626 | I21: =P21/$Q21 -> 0.10079625 | J21: =J20*(1+Returns!B8) -> 31895702 | K21: =K20*(1+Returns!C8) -> 15622903 | L21: =L20*(1+Returns!D8) -> 5374609.6 | M21: =M20*(1+Returns!E8) -> 20411408 | N21: =N20*(1+Returns!F8) -> 10569114 | O21: =O20*(1+Returns!G8) -> 10711984 | P21: =P20*(1+Returns!H8) -> 10602586 | Q21: =SUM(J21:P21) -> 1.0518831e+08 | R21: =Q21*$B$3 -> 372541.92 | S21: =Q21-R21 -> 1.0481577e+08 | T21: =OR( C21<25%,C21>35%, D21<10%,D21>20%, E21<2%, E21>7%, F21<15%,F21>25%, G21<5%, G21>15%, H21<5%, H21>15%, I21<5%, I21>15% ) -> FALSE | U21: =IF($T21=TRUE, $Q21*$C$7, $J21) -> 31895702 | V21: =IF($T21=TRUE, $Q21*$C$8, $K21) -> 15622903 | W21: =IF($T21=TRUE, $Q21*$C$9, $L21) -> 5374609.6 | X21: =IF($T21=TRUE, $Q21*$C$10, $M21) -> 20411408 | Y21: =IF($T21=TRUE, $Q21*$C$11, $N21) -> 10569114 | Z21: =IF($T21=TRUE, $Q21*$C$12, $O21) -> 10711984 | AA21: =IF($T21=TRUE, $Q21*$C$13, $P21) -> 10602586 | AB21: =U21-(1-$B$3) -> 31895701 | AC21: =V21*(1-$B$3) -> 15567572 | AD21: =W21*(1-$B$3) -> 5355574.5 | AE21: =X21*(1-$B$3) -> 20339118 | AF21: =Y21*(1-$B$3) -> 10531681 | AG21: =Z21*(1-$B$3) -> 10674046 | AH21: =AA21*(1-$B$3) -> 10565036 | AI21: =SUM(AB21:AH21) -> 1.0492873e+08
A22: =Returns!A9 -> 42643 | B22: =S21 -> 1.0481577e+08 | C22: =J22/Q22 -> 0.30217933 | D22: =K22/$Q22 -> 0.15002985 | E22: =L22/$Q22 -> 0.052196093 | F22: =M22/$Q22 -> 0.19380008 | G22: =N22/$Q22 -> 0.099864181 | H22: =O22/$Q22 -> 0.099619066 | I22: =P22/$Q22 -> 0.1023114 | J22: =J21*(1+Returns!B9) -> 31897401 | K22: =K21*(1+Returns!C9) -> 15836829 | L22: =L21*(1+Returns!D9) -> 5509707.5 | M22: =M21*(1+Returns!E9) -> 20457120 | N22: =N21*(1+Returns!F9) -> 10541448 | O22: =O21*(1+Returns!G9) -> 10515575 | P22: =P21*(1+Returns!H9) -> 10799771 | Q22: =SUM(J22:P22) -> 1.0555785e+08 | R22: =Q22*$B$3 -> 373850.73 | S22: =Q22-R22 -> 1.05184e+08 | T22: =OR( C22<25%,C22>35%, D22<10%,D22>20%, E22<2%, E22>7%, F22<15%,F22>25%, G22<5%, G22>15%, H22<5%, H22>15%, I22<5%, I22>15% ) -> FALSE | U22: =IF($T22=TRUE, $Q22*$C$7, $J22) -> 31897401 | V22: =IF($T22=TRUE, $Q22*$C$8, $K22) -> 15836829 | W22: =IF($T22=TRUE, $Q22*$C$9, $L22) -> 5509707.5 | X22: =IF($T22=TRUE, $Q22*$C$10, $M22) -> 20457120 | Y22: =IF($T22=TRUE, $Q22*$C$11, $N22) -> 10541448 | Z22: =IF($T22=TRUE, $Q22*$C$12, $O22) -> 10515575 | AA22: =IF($T22=TRUE, $Q22*$C$13, $P22) -> 10799771 | AB22: =U22-(1-$B$3) -> 31897400 | AC22: =V22*(1-$B$3) -> 15780740 | AD22: =W22*(1-$B$3) -> 5490193.9 | AE22: =X22*(1-$B$3) -> 20384668 | AF22: =Y22*(1-$B$3) -> 10504114 | AG22: =Z22*(1-$B$3) -> 10478332 | AH22: =AA22*(1-$B$3) -> 10761522 | AI22: =SUM(AB22:AH22) -> 1.0529697e+08
A23: =Returns!A10 -> 42674 | B23: =S22 -> 1.05184e+08 | C23: =J23/Q23 -> 0.30376083 | D23: =K23/$Q23 -> 0.15007299 | E23: =L23/$Q23 -> 0.052957971 | F23: =M23/$Q23 -> 0.19528132 | G23: =N23/$Q23 -> 0.10055719 | H23: =O23/$Q23 -> 0.096070643 | I23: =P23/$Q23 -> 0.10129905 | J23: =J22*(1+Returns!B10) -> 31341940 | K23: =K22*(1+Returns!C10) -> 15484480 | L23: =L22*(1+Returns!D10) -> 5464185.5 | M23: =M22*(1+Returns!E10) -> 20149061 | N23: =N22*(1+Returns!F10) -> 10375457 | O23: =O22*(1+Returns!G10) -> 9912536.4 | P23: =P22*(1+Returns!H10) -> 10452002 | Q23: =SUM(J23:P23) -> 1.0317966e+08 | R23: =Q23*$B$3 -> 365427.97 | S23: =Q23-R23 -> 1.0281423e+08 | T23: =OR( C23<25%,C23>35%, D23<10%,D23>20%, E23<2%, E23>7%, F23<15%,F23>25%, G23<5%, G23>15%, H23<5%, H23>15%, I23<5%, I23>15% ) -> FALSE | U23: =IF($T23=TRUE, $Q23*$C$7, $J23) -> 31341940 | V23: =IF($T23=TRUE, $Q23*$C$8, $K23) -> 15484480 | W23: =IF($T23=TRUE, $Q23*$C$9, $L23) -> 5464185.5 | X23: =IF($T23=TRUE, $Q23*$C$10, $M23) -> 20149061 | Y23: =IF($T23=TRUE, $Q23*$C$11, $N23) -> 10375457 | Z23: =IF($T23=TRUE, $Q23*$C$12, $O23) -> 9912536.4 | AA23: =IF($T23=TRUE, $Q23*$C$13, $P23) -> 10452002 | AB23: =U23-(1-$B$3) -> 31341939 | AC23: =V23*(1-$B$3) -> 15429639 | AD23: =W23*(1-$B$3) -> 5444833.2 | AE23: =X23*(1-$B$3) -> 20077700 | AF23: =Y23*(1-$B$3) -> 10338711 | AG23: =Z23*(1-$B$3) -> 9877429.5 | AH23: =AA23*(1-$B$3) -> 10414984 | AI23: =SUM(AB23:AH23) -> 1.0292524e+08
A24: =Returns!A11 -> 42704 | B24: =S23 -> 1.0281423e+08 | C24: =J24/Q24 -> 0.31845845 | D24: =K24/$Q24 -> 0.14905984 | E24: =L24/$Q24 -> 0.051180397 | F24: =M24/$Q24 -> 0.18905871 | G24: =N24/$Q24 -> 0.098480303 | H24: =O24/$Q24 -> 0.095515074 | I24: =P24/$Q24 -> 0.098247223 | J24: =J23*(1+Returns!B11) -> 32497027 | K24: =K23*(1+Returns!C11) -> 15210780 | L24: =L23*(1+Returns!D11) -> 5222693 | M24: =M23*(1+Returns!E11) -> 19292458 | N24: =N23*(1+Returns!F11) -> 10049402 | O24: =O23*(1+Returns!G11) -> 9746816 | P24: =P23*(1+Returns!H11) -> 10025618 | Q24: =SUM(J24:P24) -> 1.0204479e+08 | R24: =Q24*$B$3 -> 361408.65 | S24: =Q24-R24 -> 1.0168339e+08 | T24: =OR( C24<25%,C24>35%, D24<10%,D24>20%, E24<2%, E24>7%, F24<15%,F24>25%, G24<5%, G24>15%, H24<5%, H24>15%, I24<5%, I24>15% ) -> FALSE | U24: =IF($T24=TRUE, $Q24*$C$7, $J24) -> 32497027 | V24: =IF($T24=TRUE, $Q24*$C$8, $K24) -> 15210780 | W24: =IF($T24=TRUE, $Q24*$C$9, $L24) -> 5222693 | X24: =IF($T24=TRUE, $Q24*$C$10, $M24) -> 19292458 | Y24: =IF($T24=TRUE, $Q24*$C$11, $N24) -> 10049402 | Z24: =IF($T24=TRUE, $Q24*$C$12, $O24) -> 9746816 | AA24: =IF($T24=TRUE, $Q24*$C$13, $P24) -> 10025618 | AB24: =U24-(1-$B$3) -> 32497026 | AC24: =V24*(1-$B$3) -> 15156909 | AD24: =W24*(1-$B$3) -> 5204196 | AE24: =X24*(1-$B$3) -> 19224130 | AF24: =Y24*(1-$B$3) -> 10013811 | AG24: =Z24*(1-$B$3) -> 9712296 | AH24: =AA24*(1-$B$3) -> 9990110.3 | AI24: =SUM(AB24:AH24) -> 1.0179848e+08
A25: =Returns!A12 -> 42735 | B25: =S24 -> 1.0168339e+08 | C25: =J25/Q25 -> 0.31912617 | D25: =K25/$Q25 -> 0.15035492 | E25: =L25/$Q25 -> 0.050149935 | F25: =M25/$Q25 -> 0.1854977 | G25: =N25/$Q25 -> 0.09755293 | H25: =O25/$Q25 -> 0.098327325 | I25: =P25/$Q25 -> 0.098991025 | J25: =J24*(1+Returns!B12) -> 33152709 | K25: =K24*(1+Returns!C12) -> 15619757 | L25: =L24*(1+Returns!D12) -> 5209871.2 | M25: =M24*(1+Returns!E12) -> 19270595 | N25: =N24*(1+Returns!F12) -> 10134374 | O25: =O24*(1+Returns!G12) -> 10214823 | P25: =P24*(1+Returns!H12) -> 10283772 | Q25: =SUM(J25:P25) -> 1.038859e+08 | R25: =Q25*$B$3 -> 367929.23 | S25: =Q25-R25 -> 1.0351797e+08 | T25: =OR( C25<25%,C25>35%, D25<10%,D25>20%, E25<2%, E25>7%, F25<15%,F25>25%, G25<5%, G25>15%, H25<5%, H25>15%, I25<5%, I25>15% ) -> FALSE | U25: =IF($T25=TRUE, $Q25*$C$7, $J25) -> 33152709 | V25: =IF($T25=TRUE, $Q25*$C$8, $K25) -> 15619757 | W25: =IF($T25=TRUE, $Q25*$C$9, $L25) -> 5209871.2 | X25: =IF($T25=TRUE, $Q25*$C$10, $M25) -> 19270595 | Y25: =IF($T25=TRUE, $Q25*$C$11, $N25) -> 10134374 | Z25: =IF($T25=TRUE, $Q25*$C$12, $O25) -> 10214823 | AA25: =IF($T25=TRUE, $Q25*$C$13, $P25) -> 10283772 | AB25: =U25-(1-$B$3) -> 33152708 | AC25: =V25*(1-$B$3) -> 15564437 | AD25: =W25*(1-$B$3) -> 5191419.6 | AE25: =X25*(1-$B$3) -> 19202345 | AF25: =Y25*(1-$B$3) -> 10098481 | AG25: =Z25*(1-$B$3) -> 10178645 | AH25: =AA25*(1-$B$3) -> 10247350 | AI25: =SUM(AB25:AH25) -> 1.0363539e+08
A26: =Returns!A13 -> 42766 | B26: =S25 -> 1.0351797e+08 | C26: =J26/Q26 -> 0.31970494 | D26: =K26/$Q26 -> 0.15285405 | E26: =L26/$Q26 -> 0.052636956 | F26: =M26/$Q26 -> 0.18296527 | G26: =N26/$Q26 -> 0.096134338 | H26: =O26/$Q26 -> 0.096590964 | I26: =P26/$Q26 -> 0.099113485 | J26: =J25*(1+Returns!B13) -> 33748938 | K26: =K25*(1+Returns!C13) -> 16135696 | L26: =L25*(1+Returns!D13) -> 5556502.7 | M26: =M25*(1+Returns!E13) -> 19314320 | N26: =N25*(1+Returns!F13) -> 10148207 | O26: =O25*(1+Returns!G13) -> 10196409 | P26: =P25*(1+Returns!H13) -> 10462694 | Q26: =SUM(J26:P26) -> 1.0556277e+08 | R26: =Q26*$B$3 -> 373868.13 | S26: =Q26-R26 -> 1.051889e+08 | T26: =OR( C26<25%,C26>35%, D26<10%,D26>20%, E26<2%, E26>7%, F26<15%,F26>25%, G26<5%, G26>15%, H26<5%, H26>15%, I26<5%, I26>15% ) -> FALSE | U26: =IF($T26=TRUE, $Q26*$C$7, $J26) -> 33748938 | V26: =IF($T26=TRUE, $Q26*$C$8, $K26) -> 16135696 | W26: =IF($T26=TRUE, $Q26*$C$9, $L26) -> 5556502.7 | X26: =IF($T26=TRUE, $Q26*$C$10, $M26) -> 19314320 | Y26: =IF($T26=TRUE, $Q26*$C$11, $N26) -> 10148207 | Z26: =IF($T26=TRUE, $Q26*$C$12, $O26) -> 10196409 | AA26: =IF($T26=TRUE, $Q26*$C$13, $P26) -> 10462694 | AB26: =U26-(1-$B$3) -> 33748937 | AC26: =V26*(1-$B$3) -> 16078549 | AD26: =W26*(1-$B$3) -> 5536823.4 | AE26: =X26*(1-$B$3) -> 19245915 | AF26: =Y26*(1-$B$3) -> 10112265 | AG26: =Z26*(1-$B$3) -> 10160297 | AH26: =AA26*(1-$B$3) -> 10425638 | AI26: =SUM(AB26:AH26) -> 1.0530843e+08
A27: =Returns!A14 -> 42794 | B27: =S26 -> 1.051889e+08 | C27: =J27/Q27 -> 0.32447694 | D27: =K27/$Q27 -> 0.1510359 | E27: =L27/$Q27 -> 0.052293927 | F27: =M27/$Q27 -> 0.18004294 | G27: =N27/$Q27 -> 0.095080836 | H27: =O27/$Q27 -> 0.097627523 | I27: =P27/$Q27 -> 0.099441933 | J27: =J26*(1+Returns!B14) -> 35077289 | K27: =K26*(1+Returns!C14) -> 16327601 | L27: =L26*(1+Returns!D14) -> 5653188.1 | M27: =M26*(1+Returns!E14) -> 19463381 | N27: =N26*(1+Returns!F14) -> 10278629 | O27: =O26*(1+Returns!G14) -> 10553936 | P27: =P26*(1+Returns!H14) -> 10750081 | Q27: =SUM(J27:P27) -> 1.081041e+08 | R27: =Q27*$B$3 -> 382868.7 | S27: =Q27-R27 -> 1.0772124e+08 | T27: =OR( C27<25%,C27>35%, D27<10%,D27>20%, E27<2%, E27>7%, F27<15%,F27>25%, G27<5%, G27>15%, H27<5%, H27>15%, I27<5%, I27>15% ) -> FALSE | U27: =IF($T27=TRUE, $Q27*$C$7, $J27) -> 35077289 | V27: =IF($T27=TRUE, $Q27*$C$8, $K27) -> 16327601 | W27: =IF($T27=TRUE, $Q27*$C$9, $L27) -> 5653188.1 | X27: =IF($T27=TRUE, $Q27*$C$10, $M27) -> 19463381 | Y27: =IF($T27=TRUE, $Q27*$C$11, $N27) -> 10278629 | Z27: =IF($T27=TRUE, $Q27*$C$12, $O27) -> 10553936 | AA27: =IF($T27=TRUE, $Q27*$C$13, $P27) -> 10750081 | AB27: =U27-(1-$B$3) -> 35077288 | AC27: =V27*(1-$B$3) -> 16269774 | AD27: =W27*(1-$B$3) -> 5633166.4 | AE27: =X27*(1-$B$3) -> 19394448 | AF27: =Y27*(1-$B$3) -> 10242225 | AG27: =Z27*(1-$B$3) -> 10516557 | AH27: =AA27*(1-$B$3) -> 10712008 | AI27: =SUM(AB27:AH27) -> 1.0784547e+08
A28: =Returns!A15 -> 42825 | B28: =S27 -> 1.0772124e+08 | C28: =J28/Q28 -> 0.32214499 | D28: =K28/$Q28 -> 0.15463209 | E28: =L28/$Q28 -> 0.053772644 | F28: =M28/$Q28 -> 0.178696 | G28: =N28/$Q28 -> 0.094020568 | H28: =O28/$Q28 -> 0.094467285 | I28: =P28/$Q28 -> 0.10226642 | J28: =J27*(1+Returns!B15) -> 35116358 | K28: =K27*(1+Returns!C15) -> 16856124 | L28: =L27*(1+Returns!D15) -> 5861644.5 | M28: =M27*(1+Returns!E15) -> 19479281 | N28: =N27*(1+Returns!F15) -> 10248987 | O28: =O27*(1+Returns!G15) -> 10297683 | P28: =P27*(1+Returns!H15) -> 11147850 | Q28: =SUM(J28:P28) -> 1.0900793e+08 | R28: =Q28*$B$3 -> 386069.74 | S28: =Q28-R28 -> 1.0862186e+08 | T28: =OR( C28<25%,C28>35%, D28<10%,D28>20%, E28<2%, E28>7%, F28<15%,F28>25%, G28<5%, G28>15%, H28<5%, H28>15%, I28<5%, I28>15% ) -> FALSE | U28: =IF($T28=TRUE, $Q28*$C$7, $J28) -> 35116358 | V28: =IF($T28=TRUE, $Q28*$C$8, $K28) -> 16856124 | W28: =IF($T28=TRUE, $Q28*$C$9, $L28) -> 5861644.5 | X28: =IF($T28=TRUE, $Q28*$C$10, $M28) -> 19479281 | Y28: =IF($T28=TRUE, $Q28*$C$11, $N28) -> 10248987 | Z28: =IF($T28=TRUE, $Q28*$C$12, $O28) -> 10297683 | AA28: =IF($T28=TRUE, $Q28*$C$13, $P28) -> 11147850 | AB28: =U28-(1-$B$3) -> 35116357 | AC28: =V28*(1-$B$3) -> 16796425 | AD28: =W28*(1-$B$3) -> 5840884.5 | AE28: =X28*(1-$B$3) -> 19410291 | AF28: =Y28*(1-$B$3) -> 10212689 | AG28: =Z28*(1-$B$3) -> 10261212 | AH28: =AA28*(1-$B$3) -> 11108368 | AI28: =SUM(AB28:AH28) -> 1.0874623e+08
A29: =Returns!A16 -> 42855 | B29: =S28 -> 1.0862186e+08 | C29: =J29/Q29 -> 0.32127753 | D29: =K29/$Q29 -> 0.15640643 | E29: =L29/$Q29 -> 0.054003596 | F29: =M29/$Q29 -> 0.17837344 | G29: =N29/$Q29 -> 0.093956594 | H29: =O29/$Q29 -> 0.093510246 | I29: =P29/$Q29 -> 0.10247217 | J29: =J28*(1+Returns!B16) -> 35464583 | K29: =K28*(1+Returns!C16) -> 17265101 | L29: =L28*(1+Returns!D16) -> 5961248 | M29: =M28*(1+Returns!E16) -> 19689953 | N29: =N28*(1+Returns!F16) -> 10371505 | O29: =O28*(1+Returns!G16) -> 10322234 | P29: =P28*(1+Returns!H16) -> 11311506 | Q29: =SUM(J29:P29) -> 1.1038613e+08 | R29: =Q29*$B$3 -> 390950.88 | S29: =Q29-R29 -> 1.0999518e+08 | T29: =OR( C29<25%,C29>35%, D29<10%,D29>20%, E29<2%, E29>7%, F29<15%,F29>25%, G29<5%, G29>15%, H29<5%, H29>15%, I29<5%, I29>15% ) -> FALSE | U29: =IF($T29=TRUE, $Q29*$C$7, $J29) -> 35464583 | V29: =IF($T29=TRUE, $Q29*$C$8, $K29) -> 17265101 | W29: =IF($T29=TRUE, $Q29*$C$9, $L29) -> 5961248 | X29: =IF($T29=TRUE, $Q29*$C$10, $M29) -> 19689953 | Y29: =IF($T29=TRUE, $Q29*$C$11, $N29) -> 10371505 | Z29: =IF($T29=TRUE, $Q29*$C$12, $O29) -> 10322234 | AA29: =IF($T29=TRUE, $Q29*$C$13, $P29) -> 11311506 | AB29: =U29-(1-$B$3) -> 35464582 | AC29: =V29*(1-$B$3) -> 17203953 | AD29: =W29*(1-$B$3) -> 5940135.3 | AE29: =X29*(1-$B$3) -> 19620218 | AF29: =Y29*(1-$B$3) -> 10334772 | AG29: =Z29*(1-$B$3) -> 10285676 | AH29: =AA29*(1-$B$3) -> 11271445 | AI29: =SUM(AB29:AH29) -> 1.1012078e+08
... A135: =Returns!A122 -> 46081 | B135: =S134 -> 2.2272433e+08 | C135: =J135/Q135 -> 0.51378408 | D135: =K135/$Q135 -> 0.14549408 | E135: =L135/$Q135 -> 0.047956909 | F135: =M135/$Q135 -> 0.08573511 | G135: =N135/$Q135 -> 0.048912384 | H135: =O135/$Q135 -> 0.064395186 | I135: =P135/$Q135 -> 0.093722255 | J135: =J134*(1+Returns!B122) -> 1.1580431e+08 | K135: =K134*(1+Returns!C122) -> 32793624 | L135: =L134*(1+Returns!D122) -> 10809243 | M135: =M134*(1+Returns!E122) -> 19324257 | N135: =N134*(1+Returns!F122) -> 11024602 | O135: =O134*(1+Returns!G122) -> 14514347 | P135: =P134*(1+Returns!H122) -> 21124519 | Q135: =SUM(J135:P135) -> 2.2539491e+08 | R135: =Q135*$B$3 -> 798273.63 | S135: =Q135-R135 -> 2.2459663e+08 | T135: =OR( C135<25%,C135>35%, D135<10%,D135>20%, E135<2%, E135>7%, F135<15%,F135>25%, G135<5%, G135>15%, H135<5%, H135>15%, I135<5%, I135>15% ) -> TRUE | U135: =IF($T135=TRUE, $Q135*$C$7, $J135) -> 67618472 | V135: =IF($T135=TRUE, $Q135*$C$8, $K135) -> 33809236 | W135: =IF($T135=TRUE, $Q135*$C$9, $L135) -> 11269745 | X135: =IF($T135=TRUE, $Q135*$C$10, $M135) -> 45078981 | Y135: =IF($T135=TRUE, $Q135*$C$11, $N135) -> 22539491 | Z135: =IF($T135=TRUE, $Q135*$C$12, $O135) -> 22539491 | AA135: =IF($T135=TRUE, $Q135*$C$13, $P135) -> 22539491 | AB135: =U135-(1-$B$3) -> 67618471 | AC135: =V135*(1-$B$3) -> 33689495 | AD135: =W135*(1-$B$3) -> 11229832 | AE135: =X135*(1-$B$3) -> 44919327 | AF135: =Y135*(1-$B$3) -> 22459663 | AG135: =Z135*(1-$B$3) -> 22459663 | AH135: =AA135*(1-$B$3) -> 22459663 | AI135: =SUM(AB135:AH135) -> 2.2483611e+08

Sheet Deviation
B1: TARGET WEIGHTS
B2: Asset Sleeve | C2: ETF | D2: Target Weight | E2: Min | F2: High
B3: Global Equity | C3: SPY | D3: 0.3 | E3: 0.25 | F3: 0.35
B4: Dev ex-US | C4: EFA | D4: 0.15 | E4: 0.1 | F4: 0.2
B5: EM | C5: EEM | D5: 0.05 | E5: 0.02 | F5: 0.07
B6: Fixed Income | C6: IEF | D6: 0.2 | E6: 0.15 | F6: 0.25
B7: Credit | C7: LQD | D7: 0.1 | E7: 0.05 | F7: 0.15
B8: Real Estate | C8: VNQ | D8: 0.1 | E8: 0.05 | F8: 0.15
B9: Infrastructure | C9: IGF | D9: 0.1 | E9: 0.05 | F9: 0.15
A15: DATE | B15: SPY DEV | C15: EFA | D15: EEM | E15: IEF | F15: LQD | G15: VNQ | H15: IGF | I15: REBALANCE
A16: ='Rebalancing Simulation'!A16 -> 42460 | B16: ='Rebalancing Simulation'!C16 -$D$3 -> 0 | C16: ='Rebalancing Simulation'!D16-Deviation!$D$4 -> 0 | D16: ='Rebalancing Simulation'!E16-Deviation!$D$5 -> 0 | E16: ='Rebalancing Simulation'!F16-Deviation!$D$6 -> 0 | F16: ='Rebalancing Simulation'!G16-Deviation!$D$7 -> 0 | G16: ='Rebalancing Simulation'!H16-Deviation!$D$8 -> 0 | H16: ='Rebalancing Simulation'!I16-Deviation!$D$9 -> 0 | I16: =IF( OR( ABS(B16)>5%, ABS(C16)>5%, ABS(D16)>2%, ABS(E16)>5%, ABS(F16)>5%, ABS(G16)>5%, ABS(H16)>5% ), 1, 0 ) -> 0
A17: ='Rebalancing Simulation'!A17 -> 42490 | B17: ='Rebalancing Simulation'!C17 -$D$3 -> -0.00061642044 | C17: ='Rebalancing Simulation'!D17-Deviation!$D$4 -> 0.0024413572 | D17: ='Rebalancing Simulation'!E17-Deviation!$D$5 -> -5.9581146e-05 | E17: ='Rebalancing Simulation'!F17-Deviation!$D$6 -> -0.0015011631 | F17: ='Rebalancing Simulation'!G17-Deviation!$D$7 -> 0.00099885356 | G17: ='Rebalancing Simulation'!H17-Deviation!$D$8 -> -0.0029166577 | H17: ='Rebalancing Simulation'!I17-Deviation!$D$9 -> 0.0016536117 | I17: =IF( OR( ABS(B17)>5%, ABS(C17)>5%, ABS(D17)>2%, ABS(E17)>5%, ABS(F17)>5%, ABS(G17)>5%, ABS(H17)>5% ), 1, 0 ) -> 0
A18: ='Rebalancing Simulation'!A18 -> 42521 | B18: ='Rebalancing Simulation'!C18 -$D$3 -> 0.0032075628 | C18: ='Rebalancing Simulation'!D18-Deviation!$D$4 -> 0.0016694897 | D18: ='Rebalancing Simulation'!E18-Deviation!$D$5 -> -0.0021379453 | E18: ='Rebalancing Simulation'!F18-Deviation!$D$6 -> -0.0025014251 | F18: ='Rebalancing Simulation'!G18-Deviation!$D$7 -> 7.1154875e-05 | G18: ='Rebalancing Simulation'!H18-Deviation!$D$8 -> -0.0011566769 | H18: ='Rebalancing Simulation'!I18-Deviation!$D$9 -> 0.00084783993 | I18: =IF( OR( ABS(B18)>5%, ABS(C18)>5%, ABS(D18)>2%, ABS(E18)>5%, ABS(F18)>5%, ABS(G18)>5%, ABS(H18)>5% ), 1, 0 ) -> 0
A19: ='Rebalancing Simulation'!A19 -> 42551 | B19: ='Rebalancing Simulation'!C19 -$D$3 -> -0.0013479651 | C19: ='Rebalancing Simulation'!D19-Deviation!$D$4 -> -0.0047285153 | D19: ='Rebalancing Simulation'!E19-Deviation!$D$5 -> -0.00087505218 | E19: ='Rebalancing Simulation'!F19-Deviation!$D$6 -> -0.00018691371 | F19: ='Rebalancing Simulation'!G19-Deviation!$D$7 -> 0.001215848 | G19: ='Rebalancing Simulation'!H19-Deviation!$D$8 -> 0.0037494097 | H19: ='Rebalancing Simulation'!I19-Deviation!$D$9 -> 0.0021731886 | I19: =IF( OR( ABS(B19)>5%, ABS(C19)>5%, ABS(D19)>2%, ABS(E19)>5%, ABS(F19)>5%, ABS(G19)>5%, ABS(H19)>5% ), 1, 0 ) -> 0
A20: ='Rebalancing Simulation'!A20 -> 42582 | B20: ='Rebalancing Simulation'!C20 -$D$3 -> 0.0010608853 | C20: ='Rebalancing Simulation'!D20-Deviation!$D$4 -> -0.0031288756 | D20: ='Rebalancing Simulation'!E20-Deviation!$D$5 -> 0.0003409448 | E20: ='Rebalancing Simulation'!F20-Deviation!$D$6 -> -0.0051675196 | F20: ='Rebalancing Simulation'!G20-Deviation!$D$7 -> -0.0002660663 | G20: ='Rebalancing Simulation'!H20-Deviation!$D$8 -> 0.0051923818 | H20: ='Rebalancing Simulation'!I20-Deviation!$D$9 -> 0.0019682495 | I20: =IF( OR( ABS(B20)>5%, ABS(C20)>5%, ABS(D20)>2%, ABS(E20)>5%, ABS(F20)>5%, ABS(G20)>5%, ABS(H20)>5% ), 1, 0 ) -> 0
A21: ='Rebalancing Simulation'!A21 -> 42613 | B21: ='Rebalancing Simulation'!C21 -$D$3 -> 0.0032247907 | C21: ='Rebalancing Simulation'!D21-Deviation!$D$4 -> -0.0014768122 | D21: ='Rebalancing Simulation'!E21-Deviation!$D$5 -> 0.001095124 | E21: ='Rebalancing Simulation'!F21-Deviation!$D$6 -> -0.0059536397 | F21: ='Rebalancing Simulation'!G21-Deviation!$D$7 -> 0.00047802859 | G21: ='Rebalancing Simulation'!H21-Deviation!$D$8 -> 0.0018362624 | H21: ='Rebalancing Simulation'!I21-Deviation!$D$9 -> 0.00079624611 | I21: =IF( OR( ABS(B21)>5%, ABS(C21)>5%, ABS(D21)>2%, ABS(E21)>5%, ABS(F21)>5%, ABS(G21)>5%, ABS(H21)>5% ), 1, 0 ) -> 0
A22: ='Rebalancing Simulation'!A22 -> 42643 | B22: ='Rebalancing Simulation'!C22 -$D$3 -> 0.0021793307 | C22: ='Rebalancing Simulation'!D22-Deviation!$D$4 -> 2.9851552e-05 | D22: ='Rebalancing Simulation'!E22-Deviation!$D$5 -> 0.0021960929 | E22: ='Rebalancing Simulation'!F22-Deviation!$D$6 -> -0.0061999201 | F22: ='Rebalancing Simulation'!G22-Deviation!$D$7 -> -0.00013581862 | G22: ='Rebalancing Simulation'!H22-Deviation!$D$8 -> -0.00038093371 | H22: ='Rebalancing Simulation'!I22-Deviation!$D$9 -> 0.0023113973 | I22: =IF( OR( ABS(B22)>5%, ABS(C22)>5%, ABS(D22)>2%, ABS(E22)>5%, ABS(F22)>5%, ABS(G22)>5%, ABS(H22)>5% ), 1, 0 ) -> 0
A23: ='Rebalancing Simulation'!A23 -> 42674 | B23: ='Rebalancing Simulation'!C23 -$D$3 -> 0.0037608331 | C23: ='Rebalancing Simulation'!D23-Deviation!$D$4 -> 7.2986041e-05 | D23: ='Rebalancing Simulation'!E23-Deviation!$D$5 -> 0.0029579713 | E23: ='Rebalancing Simulation'!F23-Deviation!$D$6 -> -0.0047186755 | F23: ='Rebalancing Simulation'!G23-Deviation!$D$7 -> 0.00055719163 | G23: ='Rebalancing Simulation'!H23-Deviation!$D$8 -> -0.0039293566 | H23: ='Rebalancing Simulation'!I23-Deviation!$D$9 -> 0.00129905 | I23: =IF( OR( ABS(B23)>5%, ABS(C23)>5%, ABS(D23)>2%, ABS(E23)>5%, ABS(F23)>5%, ABS(G23)>5%, ABS(H23)>5% ), 1, 0 ) -> 0
A24: ='Rebalancing Simulation'!A24 -> 42704 | B24: ='Rebalancing Simulation'!C24 -$D$3 -> 0.018458454 | C24: ='Rebalancing Simulation'!D24-Deviation!$D$4 -> -0.00094016458 | D24: ='Rebalancing Simulation'!E24-Deviation!$D$5 -> 0.0011803967 | E24: ='Rebalancing Simulation'!F24-Deviation!$D$6 -> -0.010941286 | F24: ='Rebalancing Simulation'!G24-Deviation!$D$7 -> -0.001519697 | G24: ='Rebalancing Simulation'!H24-Deviation!$D$8 -> -0.0044849263 | H24: ='Rebalancing Simulation'!I24-Deviation!$D$9 -> -0.0017527768 | I24: =IF( OR( ABS(B24)>5%, ABS(C24)>5%, ABS(D24)>2%, ABS(E24)>5%, ABS(F24)>5%, ABS(G24)>5%, ABS(H24)>5% ), 1, 0 ) -> 0
A25: ='Rebalancing Simulation'!A25 -> 42735 | B25: ='Rebalancing Simulation'!C25 -$D$3 -> 0.019126166 | C25: ='Rebalancing Simulation'!D25-Deviation!$D$4 -> 0.00035492325 | D25: ='Rebalancing Simulation'!E25-Deviation!$D$5 -> 0.00014993519 | E25: ='Rebalancing Simulation'!F25-Deviation!$D$6 -> -0.014502305 | F25: ='Rebalancing Simulation'!G25-Deviation!$D$7 -> -0.0024470698 | G25: ='Rebalancing Simulation'!H25-Deviation!$D$8 -> -0.0016726751 | H25: ='Rebalancing Simulation'!I25-Deviation!$D$9 -> -0.0010089747 | I25: =IF( OR( ABS(B25)>5%, ABS(C25)>5%, ABS(D25)>2%, ABS(E25)>5%, ABS(F25)>5%, ABS(G25)>5%, ABS(H25)>5% ), 1, 0 ) -> 0
A26: ='Rebalancing Simulation'!A26 -> 42766 | B26: ='Rebalancing Simulation'!C26 -$D$3 -> 0.019704943 | C26: ='Rebalancing Simulation'!D26-Deviation!$D$4 -> 0.0028540486 | D26: ='Rebalancing Simulation'!E26-Deviation!$D$5 -> 0.0026369558 | E26: ='Rebalancing Simulation'!F26-Deviation!$D$6 -> -0.017034734 | F26: ='Rebalancing Simulation'!G26-Deviation!$D$7 -> -0.0038656622 | G26: ='Rebalancing Simulation'!H26-Deviation!$D$8 -> -0.0034090363 | H26: ='Rebalancing Simulation'!I26-Deviation!$D$9 -> -0.00088651501 | I26: =IF( OR( ABS(B26)>5%, ABS(C26)>5%, ABS(D26)>2%, ABS(E26)>5%, ABS(F26)>5%, ABS(G26)>5%, ABS(H26)>5% ), 1, 0 ) -> 0
A27: ='Rebalancing Simulation'!A27 -> 42794 | B27: ='Rebalancing Simulation'!C27 -$D$3 -> 0.024476941 | C27: ='Rebalancing Simulation'!D27-Deviation!$D$4 -> 0.0010359003 | D27: ='Rebalancing Simulation'!E27-Deviation!$D$5 -> 0.002293927 | E27: ='Rebalancing Simulation'!F27-Deviation!$D$6 -> -0.01995706 | F27: ='Rebalancing Simulation'!G27-Deviation!$D$7 -> -0.0049191639 | G27: ='Rebalancing Simulation'!H27-Deviation!$D$8 -> -0.0023724774 | H27: ='Rebalancing Simulation'!I27-Deviation!$D$9 -> -0.00055806654 | I27: =IF( OR( ABS(B27)>5%, ABS(C27)>5%, ABS(D27)>2%, ABS(E27)>5%, ABS(F27)>5%, ABS(G27)>5%, ABS(H27)>5% ), 1, 0 ) -> 0
... A135: ='Rebalancing Simulation'!A135 -> 46081 | B135: ='Rebalancing Simulation'!C135 -$D$3 -> 0.21378408 | C135: ='Rebalancing Simulation'!D135-Deviation!$D$4 -> -0.0045059224 | D135: ='Rebalancing Simulation'!E135-Deviation!$D$5 -> -0.0020430911 | E135: ='Rebalancing Simulation'!F135-Deviation!$D$6 -> -0.11426489 | F135: ='Rebalancing Simulation'!G135-Deviation!$D$7 -> -0.051087616 | G135: ='Rebalancing Simulation'!H135-Deviation!$D$8 -> -0.035604814 | H135: ='Rebalancing Simulation'!I135-Deviation!$D$9 -> -0.0062777446 | I135: =IF( OR( ABS(B135)>5%, ABS(C135)>5%, ABS(D135)>2%, ABS(E135)>5%, ABS(F135)>5%, ABS(G135)>5%, ABS(H135)>5% ), 1, 0 ) -> 1

Sheet Returns
A1: Date | B1: SPY | C1: EFA | D1: EEM | E1: IEF | F1: LQD | G1: VNQ | H1: IGF | I1: Portfolio Return | J1: Portfolio Value | K1: Peak | L1: Drawdown
A2: 42429 | M2: Global Equity | N2: SPY | O2: 0.3
A3: 42460 | B3: =('Raw Data_Prices'!B3/'Raw Data_Prices'!B2)-1 -> 0.067387888 | C3: =('Raw Data_Prices'!C3/'Raw Data_Prices'!C2)-1 -> 0.065713008 | D3: =('Raw Data_Prices'!D3/'Raw Data_Prices'!D2)-1 -> 0.1296098 | E3: =('Raw Data_Prices'!E3/'Raw Data_Prices'!E2)-1 -> -0.00039733784 | F3: =('Raw Data_Prices'!F3/'Raw Data_Prices'!F2)-1 -> 0.035820285 | G3: =('Raw Data_Prices'!G3/'Raw Data_Prices'!G2)-1 -> 0.10457627 | H3: =('Raw Data_Prices'!H3/'Raw Data_Prices'!H2)-1 -> 0.086134214 | I3: {=SUMPRODUCT(B3:H3,TRANSPOSE($O$2:$O$8))} -> 0.059127417 | J3: 100000000 | K3: =J3 -> 100000000 | L3: =(J3/K3)-1 -> 0 | M3: Dev ex-US | N3: EFA | O3: 0.15
A4: 42490 | B4: =('Raw Data_Prices'!B4/'Raw Data_Prices'!B3)-1 -> 0.0037936697 | C4: =('Raw Data_Prices'!C4/'Raw Data_Prices'!C3)-1 -> 0.022231544 | D4: =('Raw Data_Prices'!D4/'Raw Data_Prices'!D3)-1 -> 0.0046618398 | E4: =('Raw Data_Prices'!E4/'Raw Data_Prices'!E3)-1 -> -0.0016893571 | F4: =('Raw Data_Prices'!F4/'Raw Data_Prices'!F3)-1 -> 0.015907519 | G4: =('Raw Data_Prices'!G4/'Raw Data_Prices'!G3)-1 -> -0.02347706 | H4: =('Raw Data_Prices'!H4/'Raw Data_Prices'!H3)-1 -> 0.022493472 | I4: {=SUMPRODUCT(B4:H4,TRANSPOSE($O$2:$O$8))} -> 0.0058604461 | J4: =J3*(1+I4) -> 1.0058604e+08 | K4: =MAX(K3,J4) -> 1.0058604e+08 | L4: =(J4/K4)-1 -> 0 | M4: EM | N4: EEM | O4: 0.05
A5: 42521 | B5: =('Raw Data_Prices'!B5/'Raw Data_Prices'!B4)-1 -> 0.017091606 | C5: =('Raw Data_Prices'!C5/'Raw Data_Prices'!C4)-1 -> -0.00082068117 | D5: =('Raw Data_Prices'!D5/'Raw Data_Prices'!D4)-1 -> -0.037530057 | E5: =('Raw Data_Prices'!E5/'Raw Data_Prices'!E4)-1 -> -0.00079633685 | F5: =('Raw Data_Prices'!F5/'Raw Data_Prices'!F4)-1 -> -0.0049601245 | G5: =('Raw Data_Prices'!G5/'Raw Data_Prices'!G4)-1 -> 0.022470145 | H5: =('Raw Data_Prices'!H5/'Raw Data_Prices'!H4)-1 -> -0.0036961594 | I5: {=SUMPRODUCT(B5:H5,TRANSPOSE($O$2:$O$8))} -> 0.0043499956 | J5: =J4*(1+I5) -> 1.0102359e+08 | K5: =MAX(K4,J5) -> 1.0102359e+08 | L5: =(J5/K5)-1 -> 0 | M5: Fixed Income | N5: IEF | O5: 0.2
A6: 42551 | B6: =('Raw Data_Prices'!B6/'Raw Data_Prices'!B5)-1 -> 0.0034385225 | C6: =('Raw Data_Prices'!C6/'Raw Data_Prices'!C5)-1 -> -0.024229979 | D6: =('Raw Data_Prices'!D6/'Raw Data_Prices'!D5)-1 -> 0.045625304 | E6: =('Raw Data_Prices'!E6/'Raw Data_Prices'!E5)-1 -> 0.030683403 | F6: =('Raw Data_Prices'!F6/'Raw Data_Prices'!F5)-1 -> 0.030397811 | G6: =('Raw Data_Prices'!G6/'Raw Data_Prices'!G5)-1 -> 0.069309974 | H6: =('Raw Data_Prices'!H6/'Raw Data_Prices'!H5)-1 -> 0.032133009 | I6: {=SUMPRODUCT(B6:H6,TRANSPOSE($O$2:$O$8))} -> 0.018999085 | J6: =J5*(1+I6) -> 1.0294295e+08 | K6: =MAX(K5,J6) -> 1.0294295e+08 | L6: =(J6/K6)-1 -> 0 | M6: Credit | N6: LQD | O6: 0.1
